Workbook

Sheet McMaster order
A1: Revopoint scanner mount - McMaster-Carr order list
A2: Quantities are for one complete build, counted from every instance in assembly.FCStd (model saved 11 Oct 2026). The copper bar and the washers are added by hand (see Notes).
A4: Qty | B4: Part number | C4: Type | D4: Description | E4: Size | F4: Where used
A5: Screws
A6: =SUMIFS('By sub-assembly'!$G$2:$G$41,'By sub-assembly'!$D$2:$D$41,$B6) -> 4 | B6: 91292A109 | C6: Screw | D6: 18-8 stainless socket head cap screw | E6: M3 x 0.5 mm, 4 mm long | F6: M3 x 8 mm standoff kit
A7: =SUMIFS('By sub-assembly'!$G$2:$G$41,'By sub-assembly'!$D$2:$D$41,$B7) -> 16 | B7: 91292A111 | C7: Screw | D7: 18-8 stainless socket head cap screw | E7: M3 x 0.5 mm, 6 mm long | F7: M3 x 31 mm standoff kit; Latitude stepper motor assembly; Longitude stepper motor assembly
A8: =SUMIFS('By sub-assembly'!$G$2:$G$41,'By sub-assembly'!$D$2:$D$41,$B8) -> 2 | B8: 91292A112 | C8: Screw | D8: 18-8 stainless socket head cap screw | E8: M3 x 0.5 mm, 8 mm long | F8: Lat/lon stage assembly; Longitude stepper mount assembly
A9: =SUMIFS('By sub-assembly'!$G$2:$G$41,'By sub-assembly'!$D$2:$D$41,$B9) -> 12 | B9: 91292A113 | C9: Screw | D9: 18-8 stainless socket head cap screw | E9: M3 x 0.5 mm, 10 mm long | F9: M3 x 8 mm standoff kit; M3 x 31 mm standoff kit
A10: =SUMIFS('By sub-assembly'!$G$2:$G$41,'By sub-assembly'!$D$2:$D$41,$B10) -> 10 | B10: 91292A114 | C10: Screw | D10: 18-8 stainless socket head cap screw | E10: M3 x 0.5 mm, 12 mm long | F10: Lat/lon stage assembly; Longitude stepper mount assembly
A11: =SUMIFS('By sub-assembly'!$G$2:$G$41,'By sub-assembly'!$D$2:$D$41,$B11) -> 12 | B11: 91355A081 | C11: Screw | D11: Black-oxide alloy steel flanged button head screw | E11: 1/4"-20, 1/2" long | F11: Foot bumper; 1/4"-20 x 63.5 mm standoff kit
A13: Nuts
A14: =SUMIFS('By sub-assembly'!$G$2:$G$41,'By sub-assembly'!$D$2:$D$41,$B14) -> 12 | B14: 94150A325 | C14: Nut | D14: 316 stainless hex nut | E14: M3 x 0.5 mm, 5.5 mm wide, 2.4 mm thick | F14: Lat/lon stage assembly; Longitude stepper mount assembly
A16: Washers
A17: =SUMIFS('By sub-assembly'!$G$2:$G$41,'By sub-assembly'!$D$2:$D$41,$B17) -> 2 | B17: 96659A106 | C17: Washer | D17: 18-8 stainless SAE washer | E17: 1/4" screw size, 0.281" ID, 0.625" OD | F17: Scanner mount (not modeled)
A19: Standoffs
A20: =SUMIFS('By sub-assembly'!$G$2:$G$41,'By sub-assembly'!$D$2:$D$41,$B20) -> 4 | B20: 95947A004 | C20: Standoff | D20: Aluminum female-threaded hex standoff | E20: M3 x 0.5 mm, 8 mm long, 4.5 mm hex | F20: M3 x 8 mm standoff kit
A21: =SUMIFS('By sub-assembly'!$G$2:$G$41,'By sub-assembly'!$D$2:$D$41,$B21) -> 8 | B21: 95947A063 | C21: Standoff | D21: Aluminum female-threaded hex standoff | E21: M3 x 0.5 mm, 31 mm long, 6 mm hex | F21: M3 x 31 mm standoff kit
A22: =SUMIFS('By sub-assembly'!$G$2:$G$41,'By sub-assembly'!$D$2:$D$41,$B22) -> 4 | B22: 91780A363 | C22: Standoff | D22: Aluminum female-threaded hex standoff | E22: 1/4"-20, 2-1/2" (63.5 mm) long, 1/2" hex | F22: 1/4"-20 x 63.5 mm standoff kit
A24: Bumpers
A25: =SUMIFS('By sub-assembly'!$G$2:$G$41,'By sub-assembly'!$D$2:$D$41,$B25) -> 4 | B25: 9546K551 | C25: Bumper | D25: Neoprene bumper, threaded stud/insert | E25: 3/4" dia x 5/8" high, 1/4"-20 | F25: Foot bumper
A27: Knobs
A28: =SUMIFS('By sub-assembly'!$G$2:$G$41,'By sub-assembly'!$D$2:$D$41,$B28) -> 1 | B28: 7129T33 | C28: Knob | D28: Black phenolic five-arm knob | E28: 32.6 mm across arms, approx. 5/16" threaded bore | F28: Top level (assembly)
A30: Bar stock
A31: =ROUNDUP('Full BOM'!A33*1.25/6,0) -> 1 | B31: 89275K36 | C31: Bar | D31: Multipurpose 110 copper bar | E31: 1/2" thick, 1/2" wide, 1/2 ft (6") long | F31: Counterweights: cut into two ~1.25" (32 mm) pieces
A33: =SUM(A6:A32) -> 92 | D33: Total McMaster pieces

Sheet Full BOM
A1: Revopoint scanner mount - full bill of materials
A3: Qty | B3: Part ref. | C3: Type | D3: Description | E3: Size | F3: Source
A4: McMaster-Carr hardware
A5: ='McMaster order'!A25 -> 4 | B5: 9546K551 | C5: Bumper | D5: Neoprene bumper, threaded stud/insert | E5: 3/4" dia x 5/8" high, 1/4"-20 | F5: McMaster-Carr
A6: ='McMaster order'!A28 -> 1 | B6: 7129T33 | C6: Knob | D6: Black phenolic five-arm knob | E6: 32.6 mm across arms, approx. 5/16" threaded bore | F6: McMaster-Carr
A7: ='McMaster order'!A14 -> 12 | B7: 94150A325 | C7: Nut | D7: 316 stainless hex nut | E7: M3 x 0.5 mm, 5.5 mm wide, 2.4 mm thick | F7: McMaster-Carr
A8: ='McMaster order'!A7 -> 16 | B8: 91292A111 | C8: Screw | D8: 18-8 stainless socket head cap screw | E8: M3 x 0.5 mm, 6 mm long | F8: McMaster-Carr
A9: ='McMaster order'!A9 -> 12 | B9: 91292A113 | C9: Screw | D9: 18-8 stainless socket head cap screw | E9: M3 x 0.5 mm, 10 mm long | F9: McMaster-Carr
A10: ='McMaster order'!A11 -> 12 | B10: 91355A081 | C10: Screw | D10: Black-oxide alloy steel flanged button head screw | E10: 1/4"-20, 1/2" long | F10: McMaster-Carr
A11: ='McMaster order'!A10 -> 10 | B11: 91292A114 | C11: Screw | D11: 18-8 stainless socket head cap screw | E11: M3 x 0.5 mm, 12 mm long | F11: McMaster-Carr
A12: ='McMaster order'!A6 -> 4 | B12: 91292A109 | C12: Screw | D12: 18-8 stainless socket head cap screw | E12: M3 x 0.5 mm, 4 mm long | F12: McMaster-Carr
A13: ='McMaster order'!A8 -> 2 | B13: 91292A112 | C13: Screw | D13: 18-8 stainless socket head cap screw | E13: M3 x 0.5 mm, 8 mm long | F13: McMaster-Carr
A14: ='McMaster order'!A21 -> 8 | B14: 95947A063 | C14: Standoff | D14: Aluminum female-threaded hex standoff | E14: M3 x 0.5 mm, 31 mm long, 6 mm hex | F14: McMaster-Carr
A15: ='McMaster order'!A22 -> 4 | B15: 91780A363 | C15: Standoff | D15: Aluminum female-threaded hex standoff | E15: 1/4"-20, 2-1/2" (63.5 mm) long, 1/2" hex | F15: McMaster-Carr
A16: ='McMaster order'!A20 -> 4 | B16: 95947A004 | C16: Standoff | D16: Aluminum female-threaded hex standoff | E16: M3 x 0.5 mm, 8 mm long, 4.5 mm hex | F16: McMaster-Carr
A17: ='McMaster order'!A17 -> 2 | B17: 96659A106 | C17: Washer | D17: 18-8 stainless SAE washer | E17: 1/4" screw size, 0.281" ID, 0.625" OD | F17: McMaster-Carr
A19: Laser-cut plates
A20: =SUMIFS('By sub-assembly'!$G$2:$G$41,'By sub-assembly'!$E$2:$E$41,$D20&IF($E20="-",""," - "&$E20)) -> 1 | C20: Plate | D20: Base plate | E20: 374 x 352 x 6.7 mm | F20: Ponoko - 6.7mm Amber Bamboo Plywood - Laser Cutting
A21: =SUMIFS('By sub-assembly'!$G$2:$G$41,'By sub-assembly'!$E$2:$E$41,$D21&IF($E21="-",""," - "&$E21)) -> 1 | C21: Plate | D21: Lat/lon plate | E21: 230 x 140 x 6.7 mm | F21: Ponoko - 6.7mm Amber Bamboo Plywood - Laser Cutting
A22: =SUMIFS('By sub-assembly'!$G$2:$G$41,'By sub-assembly'!$E$2:$E$41,$D22&IF($E22="-",""," - "&$E22)) -> 1 | C22: Plate | D22: Scanner mount plate | E22: 268 x 228 x 6.7 mm | F22: Ponoko - 6.7mm Amber Bamboo Plywood - Laser Cutting
A24: 3D printed parts
A25: =SUMIFS('By sub-assembly'!$G$2:$G$41,'By sub-assembly'!$E$2:$E$41,$D25&IF($E25="-",""," - "&$E25)) -> 2 | C25: Printed part | D25: Counterweight clamp | E25: 22.5 x 14.9 x 14.7 mm | F25: Xometry - Nylon 12, White, Color: As Printed, Off White (Natural)
A26: =SUMIFS('By sub-assembly'!$G$2:$G$41,'By sub-assembly'!$E$2:$E$41,$D26&IF($E26="-",""," - "&$E26)) -> 2 | C26: Printed part | D26: Latitude stepper mount | E26: 76 x 40 x 50 mm | F26: Xometry - Nylon 12, White, Color: As Printed, Off White (Natural)
A27: =SUMIFS('By sub-assembly'!$G$2:$G$41,'By sub-assembly'!$E$2:$E$41,$D27&IF($E27="-",""," - "&$E27)) -> 1 | C27: Printed part | D27: Longitude stepper mount | E27: 138 x 30 x 50 mm | F27: Xometry - Nylon 12, White, Color: As Printed, Off White (Natural)
A28: =SUMIFS('By sub-assembly'!$G$2:$G$41,'By sub-assembly'!$E$2:$E$41,$D28&IF($E28="-",""," - "&$E28)) -> 1 | C28: Printed part | D28: Latitude idle arm | E28: 37.8 x 40 x 23 mm | F28: Xometry - Nylon 12, White, Color: As Printed, Off White (Natural)
A29: =SUMIFS('By sub-assembly'!$G$2:$G$41,'By sub-assembly'!$E$2:$E$41,$D29&IF($E29="-",""," - "&$E29)) -> 1 | C29: Printed part | D29: Latitude stepper arm | E29: 38.0 x 40 x 16 mm | F29: Xometry - Nylon 12, White, Color: As Printed, Off White (Natural)
A30: =SUMIFS('By sub-assembly'!$G$2:$G$41,'By sub-assembly'!$E$2:$E$41,$D30&IF($E30="-",""," - "&$E30)) -> 1 | C30: Printed part | D30: Longitude plate | E30: 20.0 x 15 x 20 mm | F30: Xometry - Nylon 12, White, Color: As Printed, Off White (Natural)
A32: Cut from bar stock
A33: =SUMIFS('By sub-assembly'!$G$2:$G$41,'By sub-assembly'!$E$2:$E$41,$D33&IF($E33="-",""," - "&$E33)) -> 2 | C33: Bar stock | D33: Counterweight, cut from copper bar | E33: 1/2" x 1/2" x about 1.25" (32 mm) long | F33: Cut from McMaster-Carr 89275K36 (see McMaster order)
A35: Purchased electronics and motors
A36: =SUMIFS('By sub-assembly'!$G$2:$G$41,'By sub-assembly'!$E$2:$E$41,$D36&IF($E36="-",""," - "&$E36)) -> 1 | C36: Electronics | D36: BigTreeTech SKR Mini E3 V3.0 stepper controller board | E36: 105.3 x 70.3 x 18.2 mm | F36: Purchased
A37: =SUMIFS('By sub-assembly'!$G$2:$G$41,'By sub-assembly'!$E$2:$E$41,$D37&IF($E37="-",""," - "&$E37)) -> 1 | C37: Motor | D37: STEPPERONLINE Nema 17 stepper motor, bipolar, 4-lead | E37: 2 A, 55 Ncm, 1.8° step | F37: STEPPERONLINE (modeled as McMaster 6627T67)
A38: =SUMIFS('By sub-assembly'!$G$2:$G$41,'By sub-assembly'!$E$2:$E$41,$D38&IF($E38="-",""," - "&$E38)) -> 1 | C38: Motor | D38: STEPPERONLINE Nema 17 pancake stepper motor, bipolar, 4-lead | E38: 1 A, 17 Ncm, 1.8° step | F38: STEPPERONLINE (modeled as McMaster 6627T64)
A39: =SUMIFS('By sub-assembly'!$G$2:$G$41,'By sub-assembly'!$E$2:$E$41,$D39&IF($E39="-",""," - "&$E39)) -> 2 | C39: Cable | D39: Stepper motor cable, XH2.54 4-pin to 6-pin | E39: 1.5 m | F39: Amazon, sold in 3-packs (one pack covers both motors)
A40: =SUMIFS('By sub-assembly'!$G$2:$G$41,'By sub-assembly'!$E$2:$E$41,$D40&IF($E40="-",""," - "&$E40)) -> 1 | C40: Power supply | D40: 24 V DC power supply for the control board | E40: 6 A, 100-240 V AC in, 5.5 x 2.1 mm jack with terminal connector | F40: Amazon
A42: Reference geometry (not purchased)
A43: =SUMIFS('By sub-assembly'!$G$2:$G$41,'By sub-assembly'!$E$2:$E$41,$D43&IF($E43="-",""," - "&$E43)) -> 1 | C43: Reference | D43: Revopoint scanner clamp joint | E43: - | F43: Reference geometry - not purchased
A44: =SUMIFS('By sub-assembly'!$G$2:$G$41,'By sub-assembly'!$E$2:$E$41,$D44&IF($E44="-",""," - "&$E44)) -> 1 | C44: Reference | D44: Revopoint Mini scanner body | E44: - | F44: Reference geometry - not purchased
A45: =SUMIFS('By sub-assembly'!$G$2:$G$41,'By sub-assembly'!$E$2:$E$41,$D45&IF($E45="-",""," - "&$E45)) -> 1 | C45: Reference | D45: Revopoint Mini tripod mount | E45: - | F45: Reference geometry - not purchased
A46: =SUMIFS('By sub-assembly'!$G$2:$G$41,'By sub-assembly'!$E$2:$E$41,$D46&IF($E46="-",""," - "&$E46)) -> 1 | C46: Reference | D46: Revopoint scanner tripod receiver | E46: - | F46: Reference geometry - not purchased
...

Sheet Notes
A1: How this BOM was produced
A3: Source: assembly.FCStd, saved 11 Oct 2026 14:45.
A4: The whole assembly was opened in FreeCAD and every sub-assembly expanded, giving 108 individual part instances.
A5: Quantities on the "By sub-assembly" tab are the counted inputs (blue); every other quantity in this workbook is a formula.
A7: Fastener sizes were measured from the solid geometry, not taken from the part number:
A8: - For socket head cap screws, length = overall length along the screw axis minus the measured 3.0 mm head height,
A9: and the thread diameter is twice the measured shank radius. All five screws fall on the 91292A1xx M3 series
A10: (A109 = 4 mm, A111 = 6 mm, A112 = 8 mm, A113 = 10 mm, A114 = 12 mm), which matches the measurements exactly.
A11: - 91355A081 measures 15.80 mm overall over a 6.35 mm (1/4") shank, i.e. 1/4"-20 x 1/2" under a ~3.1 mm button head.
A12: - 91780A363 measures 63.5 mm (2-1/2") long over a 12.4 mm (1/2") hex with a 1/4" bore, matching the
A13: "standoff_q20_63mm" file name.
A14: - 95947A063 measures exactly 31.0 mm long over a 6 mm hex with an M3 bore.
... A39: two are the stand-in motors.

Sheet By sub-assembly
A1: Sub-assembly | B1: Source file | C1: Instances in build | D1: Part ref. | E1: Description | F1: Qty per instance | G1: Total qty
A2: Top level (assembly) | B2: assembly.FCStd | C2: 1 | D2: 7129T33 | E2: Black phenolic five-arm knob - 32.6 mm across arms, approx. 5/16" threaded bore | F2: 1 | G2: =C2*F2 -> 1
A3: Top level (assembly) | B3: assembly.FCStd | C3: 1 | E3: Scanner mount plate - 268 x 228 x 6.7 mm | F3: 1 | G3: =C3*F3 -> 1
A4: Top level (assembly) | B4: (not modeled) | C4: 1 | D4: 96659A106 | E4: 18-8 stainless SAE washer - 1/4" screw size, 0.281" ID, 0.625" OD | F4: 2 | G4: =C4*F4 -> 2
A5: Top level (assembly) | B5: assembly.FCStd | C5: 1 | E5: Scan test object (small bust) - 34.3 x 32.5 x 65.0 mm | F5: 1 | G5: =C5*F5 -> 1
A6: Base plate assembly | B6: base_plate_assembly.FCStd | C6: 1 | E6: BigTreeTech SKR Mini E3 V3.0 stepper controller board - 105.3 x 70.3 x 18.2 mm | F6: 1 | G6: =C6*F6 -> 1
A7: Base plate assembly | B7: base_plate_assembly.FCStd | C7: 1 | E7: Base plate - 374 x 352 x 6.7 mm | F7: 1 | G7: =C7*F7 -> 1
A8: Foot bumper | B8: bumper.FCStd | C8: 4 | D8: 9546K551 | E8: Neoprene bumper, threaded stud/insert - 3/4" dia x 5/8" high, 1/4"-20 | F8: 1 | G8: =C8*F8 -> 4
A9: Foot bumper | B9: bumper.FCStd | C9: 4 | D9: 91355A081 | E9: Black-oxide alloy steel flanged button head screw - 1/4"-20, 1/2" long | F9: 1 | G9: =C9*F9 -> 4
A10: M3 x 8 mm standoff kit | B10: standoff_m3_8mm.FCStd | C10: 4 | D10: 91292A109 | E10: 18-8 stainless socket head cap screw - M3 x 0.5 mm, 4 mm long | F10: 1 | G10: =C10*F10 -> 4
A11: M3 x 8 mm standoff kit | B11: standoff_m3_8mm.FCStd | C11: 4 | D11: 91292A113 | E11: 18-8 stainless socket head cap screw - M3 x 0.5 mm, 10 mm long | F11: 1 | G11: =C11*F11 -> 4
A12: M3 x 8 mm standoff kit | B12: standoff_m3_8mm.FCStd | C12: 4 | D12: 95947A004 | E12: Aluminum female-threaded hex standoff - M3 x 0.5 mm, 8 mm long, 4.5 mm hex | F12: 1 | G12: =C12*F12 -> 4
A13: 1/4"-20 x 63.5 mm standoff kit | B13: standoff_q20_63mm.FCStd | C13: 4 | D13: 91355A081 | E13: Black-oxide alloy steel flanged button head screw - 1/4"-20, 1/2" long | F13: 2 | G13: =C13*F13 -> 8
A14: 1/4"-20 x 63.5 mm standoff kit | B14: standoff_q20_63mm.FCStd | C14: 4 | D14: 91780A363 | E14: Aluminum female-threaded hex standoff - 1/4"-20, 2-1/2" (63.5 mm) long, 1/2" hex | F14: 1 | G14: =C14*F14 -> 4
A15: Latitude stepper mount assembly | B15: stepper_lat_assembly.FCStd | C15: 2 | E15: Latitude stepper mount - 76 x 40 x 50 mm | F15: 1 | G15: =C15*F15 -> 2
A16: M3 x 31 mm standoff kit | B16: standoff_m3_31mm.FCStd | C16: 8 | D16: 91292A111 | E16: 18-8 stainless socket head cap screw - M3 x 0.5 mm, 6 mm long | F16: 1 | G16: =C16*F16 -> 8
A17: M3 x 31 mm standoff kit | B17: standoff_m3_31mm.FCStd | C17: 8 | D17: 91292A113 | E17: 18-8 stainless socket head cap screw - M3 x 0.5 mm, 10 mm long | F17: 1 | G17: =C17*F17 -> 8
A18: M3 x 31 mm standoff kit | B18: standoff_m3_31mm.FCStd | C18: 8 | D18: 95947A063 | E18: Aluminum female-threaded hex standoff - M3 x 0.5 mm, 31 mm long, 6 mm hex | F18: 1 | G18: =C18*F18 -> 8
A19: Latitude stepper motor assembly | B19: stepper_lat.FCStd | C19: 1 | E19: STEPPERONLINE Nema 17 stepper motor, bipolar, 4-lead - 2 A, 55 Ncm, 1.8° step | F19: 1 | G19: =C19*F19 -> 1
A20: Latitude stepper motor assembly | B20: stepper_lat.FCStd | C20: 1 | D20: 91292A111 | E20: 18-8 stainless socket head cap screw - M3 x 0.5 mm, 6 mm long | F20: 4 | G20: =C20*F20 -> 4
A21: Lat/lon stage assembly | B21: lat_lon_assembly.FCStd | C21: 1 | D21: 94150A325 | E21: 316 stainless hex nut - M3 x 0.5 mm, 5.5 mm wide, 2.4 mm thick | F21: 7 | G21: =C21*F21 -> 7
A22: Lat/lon stage assembly | B22: lat_lon_assembly.FCStd | C22: 1 | E22: Lat/lon plate - 230 x 140 x 6.7 mm | F22: 1 | G22: =C22*F22 -> 1
A23: Lat/lon stage assembly | B23: lat_lon_assembly.FCStd | C23: 1 | E23: Counterweight clamp - 22.5 x 14.9 x 14.7 mm | F23: 2 | G23: =C23*F23 -> 2
A24: Lat/lon stage assembly | B24: lat_lon_assembly.FCStd | C24: 1 | E24: Latitude idle arm - 37.8 x 40 x 23 mm | F24: 1 | G24: =C24*F24 -> 1
A25: Lat/lon stage assembly | B25: lat_lon_assembly.FCStd | C25: 1 | E25: Latitude stepper arm - 38.0 x 40 x 16 mm | F25: 1 | G25: =C25*F25 -> 1
A26: Lat/lon stage assembly | B26: (not modeled) | C26: 1 | E26: Counterweight, cut from copper bar - 1/2" x 1/2" x about 1.25" (32 mm) long | F26: 2 | G26: =C26*F26 -> 2
A27: Lat/lon stage assembly | B27: lat_lon_assembly.FCStd | C27: 1 | D27: 91292A112 | E27: 18-8 stainless socket head cap screw - M3 x 0.5 mm, 8 mm long | F27: 1 | G27: =C27*F27 -> 1
A28: Lat/lon stage assembly | B28: lat_lon_assembly.FCStd | C28: 1 | D28: 91292A114 | E28: 18-8 stainless socket head cap screw - M3 x 0.5 mm, 12 mm long | F28: 6 | G28: =C28*F28 -> 6
A29: Longitude stepper mount assembly | B29: stepper_lon_assembly.FCStd | C29: 1 | D29: 94150A325 | E29: 316 stainless hex nut - M3 x 0.5 mm, 5.5 mm wide, 2.4 mm thick | F29: 5 | G29: =C29*F29 -> 5
A30: Longitude stepper mount assembly | B30: stepper_lon_assembly.FCStd | C30: 1 | E30: Longitude stepper mount - 138 x 30 x 50 mm | F30: 1 | G30: =C30*F30 -> 1
A31: Longitude stepper mount assembly | B31: stepper_lon_assembly.FCStd | C31: 1 | E31: Longitude plate - 20.0 x 15 x 20 mm | F31: 1 | G31: =C31*F31 -> 1
A32: Longitude stepper mount assembly | B32: stepper_lon_assembly.FCStd | C32: 1 | D32: 91292A112 | E32: 18-8 stainless socket head cap screw - M3 x 0.5 mm, 8 mm long | F32: 1 | G32: =C32*F32 -> 1
A33: Longitude stepper mount assembly | B33: stepper_lon_assembly.FCStd | C33: 1 | D33: 91292A114 | E33: 18-8 stainless socket head cap screw - M3 x 0.5 mm, 12 mm long | F33: 4 | G33: =C33*F33 -> 4
A34: Longitude stepper motor assembly | B34: stepper_lon.FCStd | C34: 1 | E34: STEPPERONLINE Nema 17 pancake stepper motor, bipolar, 4-lead - 1 A, 17 Ncm, 1.8° step | F34: 1 | G34: =C34*F34 -> 1
A35: Longitude stepper motor assembly | B35: stepper_lon.FCStd | C35: 1 | D35: 91292A111 | E35: 18-8 stainless socket head cap screw - M3 x 0.5 mm, 6 mm long | F35: 4 | G35: =C35*F35 -> 4
A36: Wiring | B36: (not modeled) | C36: 1 | E36: Stepper motor cable, XH2.54 4-pin to 6-pin - 1.5 m | F36: 2 | G36: =C36*F36 -> 2
A37: Wiring | B37: (not modeled) | C37: 1 | E37: 24 V DC power supply for the control board - 6 A, 100-240 V AC in, 5.5 x 2.1 mm jack with terminal connector | F37: 1 | G37: =C37*F37 -> 1
A38: Revopoint scanner (reference) | B38: revopoint_assembled.FCStd | C38: 1 | E38: Revopoint scanner clamp joint | F38: 1 | G38: =C38*F38 -> 1
A39: Revopoint scanner (reference) | B39: revopoint_assembled.FCStd | C39: 1 | E39: Revopoint Mini scanner body | F39: 1 | G39: =C39*F39 -> 1
A40: Revopoint scanner (reference) | B40: revopoint_assembled.FCStd | C40: 1 | E40: Revopoint Mini tripod mount | F40: 1 | G40: =C40*F40 -> 1
...
